<?xml version="1.0" ?>
<robot name="project_arm" xmlns:xacro="http://www.ros.org/wiki/xacro">

<xacro:include filename="$(find project_arm_description)/urdf/materials.xacro" />
<xacro:include filename="$(find project_arm_description)/urdf/project_arm.trans" />
<xacro:include filename="$(find project_arm_description)/urdf/project_arm.gazebo" />

<link name="world"/>
  <joint name="world_joint" type="fixed">
    <parent link="world"/>
    <child link="base_link"/>
    <origin xyz="0 0 0" rpy="0 0 0"/>
  </joint>

<link name="base_link">
  <inertial>
    <origin xyz="-2.0655600803110916e-17 -4.131120160622183e-17 0.051086956521739134" rpy="0 0 0"/>
    <mass value="28.14486099507207"/>
    <inertia ixx="0.101403" iyy="0.101403" izz="0.152701" ixy="-0.0" iyz="-0.0" ixz="-0.0"/>
  </inertial>
  <visual>
    <origin xyz="0 0 0" rpy="0 0 0"/>
    <geometry>
      <mesh filename="package://project_arm_description/meshes/base_link.stl" scale="0.001 0.001 0.001"/>
    </geometry>
    <material name="blue"/>
  </visual>
  <collision>
    <origin xyz="0 0 0" rpy="0 0 0"/>
    <geometry>
      <mesh filename="package://project_arm_description/meshes/base_link.stl" scale="0.001 0.001 0.001"/>
    </geometry>
  </collision>
</link>

<link name="link_1_1">
  <inertial>
    <origin xyz="0.00386503222955484 9.679350306559669e-08 0.12786907929728872" rpy="0 0 0"/>
    <mass value="35.62909759848501"/>
    <inertia ixx="0.5863" iyy="0.492833" izz="0.219323" ixy="0.0" iyz="-0.0" ixz="-0.001059"/>
  </inertial>
  <visual>
    <origin xyz="-0.0 -0.0 -0.1" rpy="0 0 0"/>
    <geometry>
      <mesh filename="package://project_arm_description/meshes/link_1_1.stl" scale="0.001 0.001 0.001"/>
    </geometry>
    <material name="silver"/>
  </visual>
  <collision>
    <origin xyz="-0.0 -0.0 -0.1" rpy="0 0 0"/>
    <geometry>
      <mesh filename="package://project_arm_description/meshes/link_1_1.stl" scale="0.001 0.001 0.001"/>
    </geometry>
  </collision>
</link>

<link name="link_2_1">
  <inertial>
    <origin xyz="3.62961838471089e-06 0.06999999999999999 0.18402946055049396" rpy="0 0 0"/>
    <mass value="61.88069383495381"/>
    <inertia ixx="1.999815" iyy="1.968216" izz="0.186912" ixy="-0.0" iyz="-0.0" ixz="6e-06"/>
  </inertial>
  <visual>
    <origin xyz="-0.0 0.07 -0.4" rpy="0 0 0"/>
    <geometry>
      <mesh filename="package://project_arm_description/meshes/link_2_1.stl" scale="0.001 0.001 0.001"/>
    </geometry>
    <material name="blue"/>
  </visual>
  <collision>
    <origin xyz="-0.0 0.07 -0.4" rpy="0 0 0"/>
    <geometry>
      <mesh filename="package://project_arm_description/meshes/link_2_1.stl" scale="0.001 0.001 0.001"/>
    </geometry>
  </collision>
</link>

<link name="link_3_1">
  <inertial>
    <origin xyz="0.023515915121691596 0.060000000443758965 -1.2755581924039916e-08" rpy="0 0 0"/>
    <mass value="20.817814940876815"/>
    <inertia ixx="0.045875" iyy="0.099243" izz="0.087409" ixy="0.0" iyz="-0.0" ixz="0.0"/>
  </inertial>
  <visual>
    <origin xyz="0.0 0.06 -0.9" rpy="0 0 0"/>
    <geometry>
      <mesh filename="package://project_arm_description/meshes/link_3_1.stl" scale="0.001 0.001 0.001"/>
    </geometry>
    <material name="silver"/>
  </visual>
  <collision>
    <origin xyz="0.0 0.06 -0.9" rpy="0 0 0"/>
    <geometry>
      <mesh filename="package://project_arm_description/meshes/link_3_1.stl" scale="0.001 0.001 0.001"/>
    </geometry>
  </collision>
</link>

<link name="link_4_1">
  <inertial>
    <origin xyz="0.14579639880643086 4.781648560622813e-08 -4.1460917521440876e-07" rpy="0 0 0"/>
    <mass value="15.109308946328982"/>
    <inertia ixx="0.036295" iyy="0.158702" izz="0.173859" ixy="-0.0" iyz="0.0" ixz="1e-06"/>
  </inertial>
  <visual>
    <origin xyz="-0.14 0.0 -0.9" rpy="0 0 0"/>
    <geometry>
      <mesh filename="package://project_arm_description/meshes/link_4_1.stl" scale="0.001 0.001 0.001"/>
    </geometry>
    <material name="blue"/>
  </visual>
  <collision>
    <origin xyz="-0.14 0.0 -0.9" rpy="0 0 0"/>
    <geometry>
      <mesh filename="package://project_arm_description/meshes/link_4_1.stl" scale="0.001 0.001 0.001"/>
    </geometry>
  </collision>
</link>

<link name="link_5_1">
  <inertial>
    <origin xyz="0.025858948215740363 0.04000001716221553 -5.351775811401893e-08" rpy="0 0 0"/>
    <mass value="9.856273770853337"/>
    <inertia ixx="0.012972" iyy="0.033281" izz="0.033173" ixy="-0.0" iyz="-0.0" ixz="0.0"/>
  </inertial>
  <visual>
    <origin xyz="-0.45 0.04 -0.9" rpy="0 0 0"/>
    <geometry>
      <mesh filename="package://project_arm_description/meshes/link_5_1.stl" scale="0.001 0.001 0.001"/>
    </geometry>
    <material name="silver"/>
  </visual>
  <collision>
    <origin xyz="-0.45 0.04 -0.9" rpy="0 0 0"/>
    <geometry>
      <mesh filename="package://project_arm_description/meshes/link_5_1.stl" scale="0.001 0.001 0.001"/>
    </geometry>
  </collision>
</link>

<link name="link_6_1">
  <inertial>
    <origin xyz="0.055503279236654435 0.0 1.1102230246251565e-16" rpy="0 0 0"/>
    <mass value="2.467650399276117"/>
    <inertia ixx="0.001433" iyy="0.00564" izz="0.00564" ixy="0.0" iyz="0.0" ixz="0.0"/>
  </inertial>
  <visual>
    <origin xyz="-0.59 -0.0 -0.9" rpy="0 0 0"/>
    <geometry>
      <mesh filename="package://project_arm_description/meshes/link_6_1.stl" scale="0.001 0.001 0.001"/>
    </geometry>
    <material name="blue"/>
  </visual>
  <collision>
    <origin xyz="-0.59 -0.0 -0.9" rpy="0 0 0"/>
    <geometry>
      <mesh filename="package://project_arm_description/meshes/link_6_1.stl" scale="0.001 0.001 0.001"/>
    </geometry>
  </collision>
</link>

<link name="link_7_1">
  <inertial>
    <origin xyz="0.04914582948025081 -0.00024072529393794642 -8.731193212874189e-09" rpy="0 0 0"/>
    <mass value="0.26287558307060616"/>
    <inertia ixx="4.9e-05" iyy="0.000308" izz="0.000308" ixy="0.0" iyz="-0.0" ixz="0.0"/>
  </inertial>
  <visual>
    <origin xyz="-0.65 -0.0 -0.9" rpy="0 0 0"/>
    <geometry>
      <mesh filename="package://project_arm_description/meshes/link_7_1.stl" scale="0.001 0.001 0.001"/>
    </geometry>
    <material name="red"/>
  </visual>
  <collision>
    <origin xyz="-0.65 -0.0 -0.9" rpy="0 0 0"/>
    <geometry>
      <mesh filename="package://project_arm_description/meshes/link_7_1.stl" scale="0.001 0.001 0.001"/>
    </geometry>
  </collision>
</link>

<joint name="joint_1" type="revolute">
  <origin xyz="0.0 0.0 0.1" rpy="0 0 0"/>
  <parent link="base_link"/>
  <child link="link_1_1"/>
  <axis xyz="0.0 0.0 1.0"/>
  <limit upper="3.141593" lower="0.0" effort="1000" velocity="10"/>
</joint>

<joint name="joint_2" type="revolute">
  <origin xyz="0.0 -0.07 0.3" rpy="0 0 0"/>
  <parent link="link_1_1"/>
  <child link="link_2_1"/>
  <axis xyz="0.0 1.0 0.0"/>
  <limit upper="1.570796" lower="-1.570796" effort="1000" velocity="10"/>
</joint>

<joint name="joint_3" type="revolute">
  <origin xyz="-0.0 0.01 0.5" rpy="0 0 0"/>
  <parent link="link_2_1"/>
  <child link="link_3_1"/>
  <axis xyz="0.0 1.0 0.0"/>
  <limit upper="0.785398" lower="-3.926991" effort="1000" velocity="10"/>
</joint>

<joint name="joint_4" type="revolute">
  <origin xyz="0.14 0.06 0.0" rpy="0 0 0"/>
  <parent link="link_3_1"/>
  <child link="link_4_1"/>
  <axis xyz="1.0 0.0 0.0"/>
  <limit upper="3.141593" lower="0.0" effort="1000" velocity="10"/>
</joint>

<joint name="joint_5" type="revolute">
  <origin xyz="0.31 -0.04 0.0" rpy="0 0 0"/>
  <parent link="link_4_1"/>
  <child link="link_5_1"/>
  <axis xyz="0.0 1.0 0.0"/>
  <limit upper="2.356194" lower="-2.356194" effort="1000" velocity="10"/>
</joint>

<joint name="joint_6" type="revolute">
  <origin xyz="0.14 0.04 0.0" rpy="0 0 0"/>
  <parent link="link_5_1"/>
  <child link="link_6_1"/>
  <axis xyz="1.0 0.0 0.0"/>
  <limit upper="6.283185" lower="0.0" effort="1000" velocity="10"/>
</joint>

<joint name="joint_7" type="prismatic">
  <origin xyz="0.06 0.0 0.0" rpy="0 0 0"/>
  <parent link="link_6_1"/>
  <child link="link_7_1"/>
  <axis xyz="1.0 0.0 0.0"/>
  <limit upper="0.05" lower="0.0" effort="1000" velocity="10"/>
</joint>

</robot>
